<?xml version="1.0" ?>
<!--
  This is not a standalone urdf for kobuki. It simply defines the 'kobuki' tag that can
  be incorporated by other urdf files (e.g. turtlebot).

  See kobuki_standalone.urdf.xacro for a standalone urdf to be tested with
      kobuki_description/launch/view_model.launch
 -->
<robot name="kobuki" xmlns:xacro="http://ros.org/wiki/xacro">
  <xacro:include filename="$(find kobuki_description)/urdf/common_properties.urdf.xacro"/>
  <xacro:include filename="$(find kobuki_description)/urdf/kobuki_gazebo.urdf.xacro"/>

  <!-- Kobuki -->
  <xacro:macro name="kobuki">
    <link name="base_footprint"/>
    <!--
       Base link is set at the bottom of the base mould.
       This is done to be compatible with the way base link
       was configured for turtlebot 1. Refer to

       https://github.com/turtlebot/turtlebot/issues/40

       To put the base link at the more oft used wheel
       axis, set the z-distance from the base_footprint
       to 0.352.
      -->
    <joint name="base_joint" type="fixed">
      <origin xyz="0 0 0.0102" rpy="0 0 0" />
      <parent link="base_footprint"/>
      <child link="base_link" />
    </joint>
    <link name="base_link">
      <visual>
        <geometry>
          <!-- new mesh -->
          <mesh filename="model://kobuki_description/meshes/main_body.dae" />
        </geometry>
        <origin xyz="0.001 0 0.05199" rpy="0 0 0"/>
      </visual>
      <collision name="base">
        <geometry>
          <cylinder length="0.10938" radius="0.178"/>
        </geometry>
        <origin xyz="0.0 0 0.05949" rpy="0 0 0"/>
      </collision>
      <inertial>
        <!-- COM experimentally determined -->
        <origin xyz="0.01 0 0"/>
        <mass value="2.4"/> <!-- 2.4/2.6 kg for small/big battery pack -->
        <!-- Kobuki's inertia tensor is approximated by a cylinder with homogeneous mass distribution
             More details http://en.wikipedia.org/wiki/List_of_moment_of_inertia_tensors
             m = 2.4 kg; h = 0.09 m; r = 0.175 m
             ixx = 1/12 * m * (3 * r^2 + h^2)
             iyy = 1/12 * m * (3 * r^2 + h^2)
             izz = 1/2 * m * r^2
          -->
        <inertia ixx="0.019995" ixy="0.0" ixz="0.0"
                 iyy="0.019995" iyz="0.0"
                 izz="0.03675" />
      </inertial>
    </link>

    <joint name="wheel_left_joint" type="continuous">
      <parent link="base_link"/>
      <child link="wheel_left_link"/>
      <origin xyz="0.00 ${0.23/2} 0.0250" rpy="${-M_PI/2} 0 0"/>
      <axis xyz="0 0 1"/>
    </joint>
    <link name="wheel_left_link">
      <visual>
        <geometry>
          <mesh filename="model://kobuki_description/meshes/wheel.dae"/>
        </geometry>
        <origin xyz="0 0 0" rpy="0 0 0"/>
      </visual>
      <collision>
        <geometry>
          <cylinder length="0.0206" radius="0.035"/>
        </geometry>
        <origin rpy="0 0 0" xyz="0 0 0"/>
      </collision>
      <inertial>
        <mass value="0.01" />
        <origin xyz="0 0 0" />
        <inertia ixx="0.001" ixy="0.0" ixz="0.0"
                 iyy="0.001" iyz="0.0"
                 izz="0.001" />
      </inertial>
    </link>

    <joint name="wheel_right_joint" type="continuous">
      <parent link="base_link"/>
      <child link="wheel_right_link"/>
      <origin xyz="0.00 -${0.23/2} 0.0250" rpy="${-M_PI/2} 0 0"/>
      <axis xyz="0 0 1"/>
    </joint>
    <link name="wheel_right_link">
      <visual>
        <geometry>
          <mesh filename="model://kobuki_description/meshes/wheel.dae"/>
        </geometry>
        <origin xyz="0 0 0" rpy="0 0 0"/>
      </visual>
      <collision>
        <geometry>
          <cylinder length="0.0206" radius="0.035"/>
        </geometry>
        <origin rpy="0 0 0" xyz="0 0 0"/>
      </collision>
      <inertial>
        <mass value="0.01" />
        <origin xyz="0 0 0" />
        <inertia ixx="0.001" ixy="0.0" ixz="0.0"
                 iyy="0.001" iyz="0.0"
                 izz="0.001" />
      </inertial>
    </link>

    <joint name="caster_front_joint" type="fixed">
      <parent link="base_link"/>
      <child link="caster_front_link"/>
      <origin xyz="0.115 0.0 0.007" rpy="${-M_PI/2} 0 0"/>
    </joint>
    <link name="caster_front_link">
      <collision>
        <geometry>
          <cylinder length="0.0176" radius="0.017"/>
        </geometry>
        <origin rpy="0 0 0" xyz="0 0 0"/>
      </collision>
      <inertial>
        <mass value="0.01" />
        <origin xyz="0 0 0" />
        <inertia ixx="0.001" ixy="0.0" ixz="0.0"
                 iyy="0.001" iyz="0.0"
                 izz="0.001" />
      </inertial>
    </link>

    <joint name="caster_back_joint" type="fixed">
      <parent link="base_link"/>
      <child link="caster_back_link"/>
      <origin xyz="-0.135 0.0 0.009" rpy="${-M_PI/2} 0 0"/>
    </joint>
    <link name="caster_back_link">
      <collision>
        <geometry>
          <cylinder length="0.0176" radius="0.017"/>
        </geometry>
        <origin rpy="0 0 0" xyz="0 0 0"/>
      </collision>
      <inertial>
        <mass value="0.01" />
        <origin xyz="0 0 0" />
        <inertia ixx="0.001" ixy="0.0" ixz="0.0"
                 iyy="0.001" iyz="0.0"
                 izz="0.001" />
      </inertial>
    </link>

    <!-- Kobuki's sensors -->
    <joint name="gyro_joint" type="fixed">
      <axis xyz="0 1 0"/>
      <origin xyz="0.056 0.062 0.0202" rpy="0 0 0"/>
      <parent link="base_link"/>
      <child link="gyro_link"/>
    </joint>
    <link name="gyro_link">
      <inertial>
        <mass value="0.001"/>
        <origin xyz="0 0 0" rpy="0 0 0"/>
        <inertia ixx="0.0001" ixy="0" ixz="0"
                 iyy="0.000001" iyz="0"
                 izz="0.0001"/>
      </inertial>
    </link>

    <joint name="cliff_sensor_left_joint" type="fixed">
      <origin xyz="0.08734 0.13601 0.0214" rpy="0 ${M_PI/2} 0" />
      <parent link="base_link"/>
      <child link="cliff_sensor_left_link" />
    </joint>
    <link name="cliff_sensor_left_link">
      <inertial>
        <mass value="0.0001" />
        <origin xyz="0 0 0" />
        <inertia ixx="0.0001" ixy="0.0" ixz="0.0"
                 iyy="0.0001" iyz="0.0"
                 izz="0.0001" />
      </inertial>
    </link>

    <joint name="cliff_sensor_right_joint" type="fixed">
      <origin xyz="0.085 -0.13601 0.0214" rpy="0 ${M_PI/2} 0" />
      <parent link="base_link"/>
      <child link="cliff_sensor_right_link" />
    </joint>
    <link name="cliff_sensor_right_link">
      <inertial>
        <mass value="0.0001" />
        <origin xyz="0 0 0" />
        <inertia ixx="0.0001" ixy="0.0" ixz="0.0"
                 iyy="0.0001" iyz="0.0"
                 izz="0.0001" />
      </inertial>
    </link>

    <joint name="cliff_sensor_front_joint" type="fixed">
      <origin xyz="0.156 0.00 0.0214" rpy="0 ${M_PI/2} 0" />
      <parent link="base_link"/>
      <child link="cliff_sensor_front_link" />
    </joint>
    <link name="cliff_sensor_front_link">
      <inertial>
        <mass value="0.0001" />
        <origin xyz="0 0 0" />
        <inertia ixx="0.0001" ixy="0.0" ixz="0.0"
                 iyy="0.0001" iyz="0.0"
                 izz="0.0001" />
      </inertial>
    </link>

    <gazebo>
      <plugin name="differential_drive_controller" filename="libgazebo_ros_diff_drive.so">
        <update_rate>10</update_rate>
        <left_joint>wheel_left_joint</left_joint>
        <right_joint>wheel_right_joint</right_joint>
        <wheel_separation>0.230</wheel_separation>
        <wheel_diameter>0.070</wheel_diameter>
        <max_wheel_torque>1.0</max_wheel_torque>
        <max_wheel_acceleration>1.0</max_wheel_acceleration>
        <command_topic>cmd_vel</command_topic>
        <!-- output -->
        <publish_odom>true</publish_odom>
        <publish_odom_tf>true</publish_odom_tf>
        <publish_wheel_tf>true</publish_wheel_tf>
        <odometry_topic>odom</odometry_topic>
        <odometry_frame>odom</odometry_frame>
        <robot_base_frame>base_link</robot_base_frame>
	    </plugin>
	  </gazebo>

     <gazebo reference="camera_link">
  <sensor name="camera" type="depth">
    <update_rate>30</update_rate>
    <camera>
      <horizontal_fov>1.047198</horizontal_fov>
      <image>
        <width>640</width>
        <height>480</height>
        <format>R8G8B8</format>
      </image>
      <clip>
        <near>0.05</near>
        <far>3</far>
      </clip>
    </camera>
    <plugin name="camera_controller" filename="libgazebo_ros_camera.so">
      <baseline>0.2</baseline>
      <alwaysOn>true</alwaysOn>
      <updateRate>1.0</updateRate>
      <imageTopicName>/camera/color/image_raw</imageTopicName>
      <cameraInfoTopicName>/camera/color/camera_info</cameraInfoTopicName>
      <depthImageTopicName>/camera/depth/image_raw</depthImageTopicName>
      <depthImageInfoTopicName>/camera/depth/camera_info</depthImageInfoTopicName>
      <pointCloudTopicName>/camera/depth/points</pointCloudTopicName>
      <frameName>camera_depth_frame</frameName>
      <pointCloudCutoff>0.5</pointCloudCutoff>
      <pointCloudCutoffMax>3.0</pointCloudCutoffMax>
      <distortionK1>0.00000001</distortionK1>
      <distortionK2>0.00000001</distortionK2>
      <distortionK3>0.00000001</distortionK3>
      <distortionT1>0.00000001</distortionT1>
      <distortionT2>0.00000001</distortionT2>
      <CxPrime>0</CxPrime>
      <Cx>0</Cx>
      <Cy>0</Cy>
      <focalLength>0</focalLength>
      <hackBaseline>0</hackBaseline>
    </plugin>
  </sensor>
</gazebo>


  <gazebo reference="camera_link">
    <sensor name="lidar" type="ray">
      <always_on>true</always_on>
      <visualize>true</visualize>
      <update_rate>5</update_rate>
      <ray>
        <scan>
          <horizontal>
            <samples>360</samples>
            <resolution>1.000000</resolution>
            <min_angle>0.000000</min_angle>
            <max_angle>6.280000</max_angle>
          </horizontal>
        </scan>
        <range>
          <min>0.28</min>
          <max>3.5</max>
          <resolution>0.015000</resolution>
        </range>
        <noise>
          <type>gaussian</type>
          <mean>0.0</mean>
          <stddev>0.01</stddev>
        </noise>
      </ray>
      <plugin filename="libgazebo_ros_ray_sensor.so" name="scan">
        <ros>
          <remapping>~/out:=scan</remapping>
        </ros>
        <output_type>sensor_msgs/LaserScan</output_type>
        <frame_name>camera_link</frame_name>
      </plugin>
    </sensor>
  </gazebo>

  </xacro:macro>
</robot>
